Workbook
Name ABC: #REF!
Name Asher: #REF!
Name def: #REF!
Name RowTitleRegion1..D5: #REF!
Name RowTitleRegion2..G3: #REF!
Name RowTitleRegion4..G23: #REF!
Name RowTitleRegion5..H24: #REF!

Sheet Billability Summary 
B2: Average Billiability by Month
Q3: Mar'26
B4: Entity/Practice | C4: Active Resources | D4: 45748 | E4: 45778 | F4: 45809 | G4: 45839 | H4: 45870 | I4: 45901 | J4: 45931 | K4: 45962 | L4: 45992 | M4: 46023 | N4: 46054 | O4: 46082 | Q4: Avg Billability | R4: Avg Availability | T4: Non Billable cost from April'25 to March '26 | V4: Non Billable cost from Jan'26 to March '26
B5: NGL | C5: =COUNTIF('Availability Report - NGL'!$D:$D,"Active") | D5: =1-AVERAGEIF('Availability Report - NGL'!$D:$D,"Active",'Availability Report - NGL'!I:I) | E5: =1-AVERAGEIF('Availability Report - NGL'!$D:$D,"Active",'Availability Report - NGL'!J:J) | F5: =1-AVERAGEIF('Availability Report - NGL'!$D:$D,"Active",'Availability Report - NGL'!K:K) | G5: =1-AVERAGEIF('Availability Report - NGL'!$D:$D,"Active",'Availability Report - NGL'!L:L) | H5: =1-AVERAGEIF('Availability Report - NGL'!$D:$D,"Active",'Availability Report - NGL'!M:M) | I5: =1-AVERAGEIF('Availability Report - NGL'!$D:$D,"Active",'Availability Report - NGL'!N:N) | J5: =1-AVERAGEIF('Availability Report - NGL'!$D:$D,"Active",'Availability Report - NGL'!O:O) | K5: =1-AVERAGEIF('Availability Report - NGL'!$D:$D,"Active",'Availability Report - NGL'!P:P) | L5: =1-AVERAGEIF('Availability Report - NGL'!$D:$D,"Active",'Availability Report - NGL'!Q:Q) | M5: =1-AVERAGEIF('Availability Report - NGL'!$D:$D,"Active",'Availability Report - NGL'!R:R) | N5: =1-AVERAGEIF('Availability Report - NGL'!$D:$D,"Active",'Availability Report - NGL'!S:S) | O5: =1-AVERAGEIF('Availability Report - NGL'!$D:$D,"Active",'Availability Report - NGL'!T:T) | Q5: =AVERAGE(N5:O5) | R5: =1-Q5
B6: nxzen - India | C6: =COUNTIF('Availability Report - YTPL'!$D$5:$D$191,"Active")-2 | D6: =1-AVERAGEIF('Availability Report - YTPL'!$D:$D,"Active",'Availability Report - YTPL'!I:I) | E6: =1-AVERAGEIF('Availability Report - YTPL'!$D:$D,"Active",'Availability Report - YTPL'!J:J) | F6: =1-AVERAGEIF('Availability Report - YTPL'!$D:$D,"Active",'Availability Report - YTPL'!K:K) | G6: =1-AVERAGEIF('Availability Report - YTPL'!$D:$D,"Active",'Availability Report - YTPL'!L:L) | H6: =1-AVERAGEIF('Availability Report - YTPL'!$D:$D,"Active",'Availability Report - YTPL'!M:M) | I6: =1-AVERAGEIF('Availability Report - YTPL'!$D:$D,"Active",'Availability Report - YTPL'!N:N) | J6: =1-AVERAGEIF('Availability Report - YTPL'!$D:$D,"Active",'Availability Report - YTPL'!O:O) | K6: =1-AVERAGEIF('Availability Report - YTPL'!$D:$D,"Active",'Availability Report - YTPL'!P:P) | L6: =1-AVERAGEIF('Availability Report - YTPL'!$D:$D,"Active",'Availability Report - YTPL'!Q:Q) | M6: =1-AVERAGEIF('Availability Report - YTPL'!$D:$D,"Active",'Availability Report - YTPL'!R:R) | N6: =1-AVERAGEIF('Availability Report - YTPL'!$D:$D,"Active",'Availability Report - YTPL'!S:S) | O6: =1-AVERAGEIF('Availability Report - YTPL'!$D:$D,"Active",'Availability Report - YTPL'!T:T) | Q6: =AVERAGE(N6:O6) | R6: =1-Q6 | T6: =+SUMIF('Availability Report - YTPL'!$D:$D,"Active",'Availability Report - YTPL'!#REF!) | V6: =+SUMIF('Availability Report - YTPL'!$D:$D,"Active",'Availability Report - YTPL'!#REF!)
B7: D&E - INDIA | C7: =COUNTIFS('Availability Report - YTPL'!D:D,"Active",'Availability Report - YTPL'!E:E,"D&E")-2 | D7: =1-AVERAGEIF('Availability Report - YTPL'!$D:$D,"Active",'Availability Report - YTPL'!I:I) | E7: =1-AVERAGEIF('Availability Report - YTPL'!$D:$D,"Active",'Availability Report - YTPL'!J:J) | F7: =1-AVERAGEIF('Availability Report - YTPL'!$D:$D,"Active",'Availability Report - YTPL'!K:K) | G7: =1-AVERAGEIF('Availability Report - YTPL'!$D:$D,"Active",'Availability Report - YTPL'!L:L) | H7: =1-AVERAGEIF('Availability Report - YTPL'!$D:$D,"Active",'Availability Report - YTPL'!M:M) | I7: =1-AVERAGEIF('Availability Report - YTPL'!$D:$D,"Active",'Availability Report - YTPL'!N:N) | J7: =1-AVERAGEIF('Availability Report - YTPL'!$D:$D,"Active",'Availability Report - YTPL'!O:O) | K7: =1-AVERAGEIF('Availability Report - YTPL'!$D:$D,"Active",'Availability Report - YTPL'!P:P) | L7: =1-AVERAGEIF('Availability Report - YTPL'!$D:$D,"Active",'Availability Report - YTPL'!Q:Q) | M7: =1-AVERAGEIF('Availability Report - YTPL'!$D:$D,"Active",'Availability Report - YTPL'!R:R) | N7: =1-AVERAGEIF('Availability Report - YTPL'!$D:$D,"Active",'Availability Report - YTPL'!S:S) | O7: =1-AVERAGEIF('Availability Report - YTPL'!$D:$D,"Active",'Availability Report - YTPL'!T:T) | Q7: =AVERAGE(N7:O7) | R7: =1-Q7 | T7: =SUMIFS('Availability Report - YTPL'!#REF!,'Availability Report - YTPL'!$E:$E,"D&E",'Availability Report - YTPL'!D:D,"Active") | V7: =SUMIFS('Availability Report - YTPL'!#REF!,'Availability Report - YTPL'!$E:$E,"D&E",'Availability Report - YTPL'!D:D,"Active")
Q9: Mar'26
B10: Function | C10: Active Resources | D10: 45748 | E10: 45778 | F10: 45809 | G10: 45839 | H10: 45870 | I10: 45901 | J10: 45931 | K10: 45962 | L10: 45992 | M10: 46023 | N10: 46054 | O10: 46082 | Q10: Avg Billability | R10: Avg Availability | T10: Non Billable cost from April'25 to March '26 | V10: Non Billable cost from Jan'26 to March '26
B11: Digital & Engineering Services | C11: =COUNTIFS('Availability Report - NGL'!$F:$F,'Billability Summary '!$B11,'Availability Report - NGL'!$D:$D,"Active") | D11: =1-AVERAGEIFS('Availability Report - NGL'!I:I,'Availability Report - NGL'!$D:$D,"Active",'Availability Report - NGL'!$F:$F,'Billability Summary '!$B11) | E11: =1-AVERAGEIFS('Availability Report - NGL'!J:J,'Availability Report - NGL'!$D:$D,"Active",'Availability Report - NGL'!$F:$F,'Billability Summary '!$B11) | F11: =1-AVERAGEIFS('Availability Report - NGL'!K:K,'Availability Report - NGL'!$D:$D,"Active",'Availability Report - NGL'!$F:$F,'Billability Summary '!$B11) | G11: =1-AVERAGEIFS('Availability Report - NGL'!L:L,'Availability Report - NGL'!$D:$D,"Active",'Availability Report - NGL'!$F:$F,'Billability Summary '!$B11) | H11: =1-AVERAGEIFS('Availability Report - NGL'!M:M,'Availability Report - NGL'!$D:$D,"Active",'Availability Report - NGL'!$F:$F,'Billability Summary '!$B11) | I11: =1-AVERAGEIFS('Availability Report - NGL'!N:N,'Availability Report - NGL'!$D:$D,"Active",'Availability Report - NGL'!$F:$F,'Billability Summary '!$B11) | J11: =1-AVERAGEIFS('Availability Report - NGL'!O:O,'Availability Report - NGL'!$D:$D,"Active",'Availability Report - NGL'!$F:$F,'Billability Summary '!$B11) | K11: =1-AVERAGEIFS('Availability Report - NGL'!P:P,'Availability Report - NGL'!$D:$D,"Active",'Availability Report - NGL'!$F:$F,'Billability Summary '!$B11) | L11: =1-AVERAGEIFS('Availability Report - NGL'!Q:Q,'Availability Report - NGL'!$D:$D,"Active",'Availability Report - NGL'!$F:$F,'Billability Summary '!$B11) | M11: =1-AVERAGEIFS('Availability Report - NGL'!R:R,'Availability Report - NGL'!$D:$D,"Active",'Availability Report - NGL'!$F:$F,'Billability Summary '!$B11) | N11: =1-AVERAGEIFS('Availability Report - NGL'!S:S,'Availability Report - NGL'!$D:$D,"Active",'Availability Report - NGL'!$F:$F,'Billability Summary '!$B11) | O11: =1-AVERAGEIFS('Availability Report - NGL'!T:T,'Availability Report - NGL'!$D:$D,"Active",'Availability Report - NGL'!$F:$F,'Billability Summary '!$B11) | Q11: =AVERAGE(N11:O11) | R11: =1-Q11 | T11: =+SUMIFS('Availability Report - NGL'!#REF!,'Availability Report - NGL'!$F:$F,'Billability Summary '!B11,'Availability Report - NGL'!$D:$D,"Active") | V11: =+SUMIFS('Availability Report - NGL'!#REF!,'Availability Report - NGL'!$F:$F,'Billability Summary '!B11,'Availability Report - NGL'!$D:$D,"Active")
B12: Growth | C12: =COUNTIFS('Availability Report - NGL'!$F:$F,'Billability Summary '!$B12,'Availability Report - NGL'!$D:$D,"Active") | D12: =1-AVERAGEIFS('Availability Report - NGL'!I:I,'Availability Report - NGL'!$D:$D,"Active",'Availability Report - NGL'!$F:$F,'Billability Summary '!$B12) | E12: =1-AVERAGEIFS('Availability Report - NGL'!J:J,'Availability Report - NGL'!$D:$D,"Active",'Availability Report - NGL'!$F:$F,'Billability Summary '!$B12) | F12: =1-AVERAGEIFS('Availability Report - NGL'!K:K,'Availability Report - NGL'!$D:$D,"Active",'Availability Report - NGL'!$F:$F,'Billability Summary '!$B12) | G12: =1-AVERAGEIFS('Availability Report - NGL'!L:L,'Availability Report - NGL'!$D:$D,"Active",'Availability Report - NGL'!$F:$F,'Billability Summary '!$B12) | H12: =1-AVERAGEIFS('Availability Report - NGL'!M:M,'Availability Report - NGL'!$D:$D,"Active",'Availability Report - NGL'!$F:$F,'Billability Summary '!$B12) | I12: =1-AVERAGEIFS('Availability Report - NGL'!N:N,'Availability Report - NGL'!$D:$D,"Active",'Availability Report - NGL'!$F:$F,'Billability Summary '!$B12) | J12: =1-AVERAGEIFS('Availability Report - NGL'!O:O,'Availability Report - NGL'!$D:$D,"Active",'Availability Report - NGL'!$F:$F,'Billability Summary '!$B12) | K12: =1-AVERAGEIFS('Availability Report - NGL'!P:P,'Availability Report - NGL'!$D:$D,"Active",'Availability Report - NGL'!$F:$F,'Billability Summary '!$B12) | L12: =1-AVERAGEIFS('Availability Report - NGL'!Q:Q,'Availability Report - NGL'!$D:$D,"Active",'Availability Report - NGL'!$F:$F,'Billability Summary '!$B12) | M12: =1-AVERAGEIFS('Availability Report - NGL'!R:R,'Availability Report - NGL'!$D:$D,"Active",'Availability Report - NGL'!$F:$F,'Billability Summary '!$B12) | N12: =1-AVERAGEIFS('Availability Report - NGL'!S:S,'Availability Report - NGL'!$D:$D,"Active",'Availability Report - NGL'!$F:$F,'Billability Summary '!$B12) | O12: =1-AVERAGEIFS('Availability Report - NGL'!T:T,'Availability Report - NGL'!$D:$D,"Active",'Availability Report - NGL'!$F:$F,'Billability Summary '!$B12) | Q12: =AVERAGE(N12:O12) | R12: =1-Q12
B13: GCC | C13: =COUNTIFS('Availability Report - NGL'!$F:$F,'Billability Summary '!$B13,'Availability Report - NGL'!$D:$D,"Active") | D13: =1-AVERAGEIFS('Availability Report - NGL'!I:I,'Availability Report - NGL'!$D:$D,"Active",'Availability Report - NGL'!$F:$F,'Billability Summary '!$B13) | E13: =1-AVERAGEIFS('Availability Report - NGL'!J:J,'Availability Report - NGL'!$D:$D,"Active",'Availability Report - NGL'!$F:$F,'Billability Summary '!$B13) | F13: =1-AVERAGEIFS('Availability Report - NGL'!K:K,'Availability Report - NGL'!$D:$D,"Active",'Availability Report - NGL'!$F:$F,'Billability Summary '!$B13) | G13: =1-AVERAGEIFS('Availability Report - NGL'!L:L,'Availability Report - NGL'!$D:$D,"Active",'Availability Report - NGL'!$F:$F,'Billability Summary '!$B13) | H13: =1-AVERAGEIFS('Availability Report - NGL'!M:M,'Availability Report - NGL'!$D:$D,"Active",'Availability Report - NGL'!$F:$F,'Billability Summary '!$B13) | I13: =1-AVERAGEIFS('Availability Report - NGL'!N:N,'Availability Report - NGL'!$D:$D,"Active",'Availability Report - NGL'!$F:$F,'Billability Summary '!$B13) | J13: =1-AVERAGEIFS('Availability Report - NGL'!O:O,'Availability Report - NGL'!$D:$D,"Active",'Availability Report - NGL'!$F:$F,'Billability Summary '!$B13) | K13: =1-AVERAGEIFS('Availability Report - NGL'!P:P,'Availability Report - NGL'!$D:$D,"Active",'Availability Report - NGL'!$F:$F,'Billability Summary '!$B13) | L13: =1-AVERAGEIFS('Availability Report - NGL'!Q:Q,'Availability Report - NGL'!$D:$D,"Active",'Availability Report - NGL'!$F:$F,'Billability Summary '!$B13) | M13: =1-AVERAGEIFS('Availability Report - NGL'!R:R,'Availability Report - NGL'!$D:$D,"Active",'Availability Report - NGL'!$F:$F,'Billability Summary '!$B13) | N13: =1-AVERAGEIFS('Availability Report - NGL'!S:S,'Availability Report - NGL'!$D:$D,"Active",'Availability Report - NGL'!$F:$F,'Billability Summary '!$B13) | O13: =1-AVERAGEIFS('Availability Report - NGL'!T:T,'Availability Report - NGL'!$D:$D,"Active",'Availability Report - NGL'!$F:$F,'Billability Summary '!$B13) | Q13: =AVERAGE(N13:O13) | R13: =1-Q13
B14: Strategic Delivery | C14: =COUNTIFS('Availability Report - NGL'!$F:$F,'Billability Summary '!$B14,'Availability Report - NGL'!$D:$D,"Active") | D14: =1-AVERAGEIFS('Availability Report - NGL'!I:I,'Availability Report - NGL'!$D:$D,"Active",'Availability Report - NGL'!$F:$F,'Billability Summary '!$B14) | E14: =1-AVERAGEIFS('Availability Report - NGL'!J:J,'Availability Report - NGL'!$D:$D,"Active",'Availability Report - NGL'!$F:$F,'Billability Summary '!$B14) | F14: =1-AVERAGEIFS('Availability Report - NGL'!K:K,'Availability Report - NGL'!$D:$D,"Active",'Availability Report - NGL'!$F:$F,'Billability Summary '!$B14) | G14: =1-AVERAGEIFS('Availability Report - NGL'!L:L,'Availability Report - NGL'!$D:$D,"Active",'Availability Report - NGL'!$F:$F,'Billability Summary '!$B14) | H14: =1-AVERAGEIFS('Availability Report - NGL'!M:M,'Availability Report - NGL'!$D:$D,"Active",'Availability Report - NGL'!$F:$F,'Billability Summary '!$B14) | I14: =1-AVERAGEIFS('Availability Report - NGL'!N:N,'Availability Report - NGL'!$D:$D,"Active",'Availability Report - NGL'!$F:$F,'Billability Summary '!$B14) | J14: =1-AVERAGEIFS('Availability Report - NGL'!O:O,'Availability Report - NGL'!$D:$D,"Active",'Availability Report - NGL'!$F:$F,'Billability Summary '!$B14) | K14: =1-AVERAGEIFS('Availability Report - NGL'!P:P,'Availability Report - NGL'!$D:$D,"Active",'Availability Report - NGL'!$F:$F,'Billability Summary '!$B14) | L14: =1-AVERAGEIFS('Availability Report - NGL'!Q:Q,'Availability Report - NGL'!$D:$D,"Active",'Availability Report - NGL'!$F:$F,'Billability Summary '!$B14) | M14: =1-AVERAGEIFS('Availability Report - NGL'!R:R,'Availability Report - NGL'!$D:$D,"Active",'Availability Report - NGL'!$F:$F,'Billability Summary '!$B14) | N14: =1-AVERAGEIFS('Availability Report - NGL'!S:S,'Availability Report - NGL'!$D:$D,"Active",'Availability Report - NGL'!$F:$F,'Billability Summary '!$B14) | O14: =1-AVERAGEIFS('Availability Report - NGL'!T:T,'Availability Report - NGL'!$D:$D,"Active",'Availability Report - NGL'!$F:$F,'Billability Summary '!$B14) | Q14: =AVERAGE(N14:O14) | R14: =1-Q14 | T14: =+SUMIFS('Availability Report - NGL'!#REF!,'Availability Report - NGL'!$F:$F,'Billability Summary '!B14,'Availability Report - NGL'!$D:$D,"Active") | V14: =+SUMIFS('Availability Report - NGL'!#REF!,'Availability Report - NGL'!$F:$F,'Billability Summary '!B14,'Availability Report - NGL'!$D:$D,"Active")
C15: =SUM(C11:C14) | T15: =SUM(T11:T14) | V15: =SUM(V11:V14)
Q16: Mar'26
B17: Practice | C17: Active Resources | D17: 45748 | E17: 45778 | F17: 45809 | G17: 45839 | H17: 45870 | I17: 45901 | J17: 45931 | K17: 45962 | L17: 45992 | M17: 46023 | N17: 46054 | O17: 46082 | Q17: Avg Billability | R17: Avg Availability | T17: Non Billable cost from April'25 to March '26 | V17: Non Billable cost from Jan'26 to March '26
B18: OT | C18: =COUNTIFS('Availability Report - NGL'!$G:$G,'Billability Summary '!$B18,'Availability Report - NGL'!$D:$D,"Active") | D18: =1-AVERAGEIFS('Availability Report - NGL'!I:I,'Availability Report - NGL'!$G:$G,'Billability Summary '!$B18,'Availability Report - NGL'!$D:$D,"Active") | E18: =1-AVERAGEIFS('Availability Report - NGL'!J:J,'Availability Report - NGL'!$G:$G,'Billability Summary '!$B18,'Availability Report - NGL'!$D:$D,"Active") | F18: =1-AVERAGEIFS('Availability Report - NGL'!K:K,'Availability Report - NGL'!$G:$G,'Billability Summary '!$B18,'Availability Report - NGL'!$D:$D,"Active") | G18: =1-AVERAGEIFS('Availability Report - NGL'!L:L,'Availability Report - NGL'!$G:$G,'Billability Summary '!$B18,'Availability Report - NGL'!$D:$D,"Active") | H18: =1-AVERAGEIFS('Availability Report - NGL'!M:M,'Availability Report - NGL'!$G:$G,'Billability Summary '!$B18,'Availability Report - NGL'!$D:$D,"Active") | I18: =1-AVERAGEIFS('Availability Report - NGL'!N:N,'Availability Report - NGL'!$G:$G,'Billability Summary '!$B18,'Availability Report - NGL'!$D:$D,"Active") | J18: =1-AVERAGEIFS('Availability Report - NGL'!O:O,'Availability Report - NGL'!$G:$G,'Billability Summary '!$B18,'Availability Report - NGL'!$D:$D,"Active") | K18: =1-AVERAGEIFS('Availability Report - NGL'!P:P,'Availability Report - NGL'!$G:$G,'Billability Summary '!$B18,'Availability Report - NGL'!$D:$D,"Active") | L18: =1-AVERAGEIFS('Availability Report - NGL'!Q:Q,'Availability Report - NGL'!$G:$G,'Billability Summary '!$B18,'Availability Report - NGL'!$D:$D,"Active") | M18: =1-AVERAGEIFS('Availability Report - NGL'!R:R,'Availability Report - NGL'!$G:$G,'Billability Summary '!$B18,'Availability Report - NGL'!$D:$D,"Active") | N18: =1-AVERAGEIFS('Availability Report - NGL'!S:S,'Availability Report - NGL'!$G:$G,'Billability Summary '!$B18,'Availability Report - NGL'!$D:$D,"Active") | O18: =1-AVERAGEIFS('Availability Report - NGL'!T:T,'Availability Report - NGL'!$G:$G,'Billability Summary '!$B18,'Availability Report - NGL'!$D:$D,"Active") | Q18: =AVERAGE(N18:O18) | R18: =1-Q18 | T18: =+SUMIFS('Availability Report - NGL'!#REF!,'Availability Report - NGL'!$G:$G,'Billability Summary '!$B18,'Availability Report - NGL'!$D:$D,"Active") | V18: =+SUMIFS('Availability Report - NGL'!#REF!,'Availability Report - NGL'!$G:$G,'Billability Summary '!$B18,'Availability Report - NGL'!$D:$D,"Active")
B19: Apps & Development | C19: =COUNTIFS('Availability Report - NGL'!$G:$G,'Billability Summary '!$B19,'Availability Report - NGL'!$D:$D,"Active") | D19: =1-AVERAGEIFS('Availability Report - NGL'!I:I,'Availability Report - NGL'!$G:$G,'Billability Summary '!$B19,'Availability Report - NGL'!$D:$D,"Active") | E19: =1-AVERAGEIFS('Availability Report - NGL'!J:J,'Availability Report - NGL'!$G:$G,'Billability Summary '!$B19,'Availability Report - NGL'!$D:$D,"Active") | F19: =1-AVERAGEIFS('Availability Report - NGL'!K:K,'Availability Report - NGL'!$G:$G,'Billability Summary '!$B19,'Availability Report - NGL'!$D:$D,"Active") | G19: =1-AVERAGEIFS('Availability Report - NGL'!L:L,'Availability Report - NGL'!$G:$G,'Billability Summary '!$B19,'Availability Report - NGL'!$D:$D,"Active") | H19: =1-AVERAGEIFS('Availability Report - NGL'!M:M,'Availability Report - NGL'!$G:$G,'Billability Summary '!$B19,'Availability Report - NGL'!$D:$D,"Active") | I19: =1-AVERAGEIFS('Availability Report - NGL'!N:N,'Availability Report - NGL'!$G:$G,'Billability Summary '!$B19,'Availability Report - NGL'!$D:$D,"Active") | J19: =1-AVERAGEIFS('Availability Report - NGL'!O:O,'Availability Report - NGL'!$G:$G,'Billability Summary '!$B19,'Availability Report - NGL'!$D:$D,"Active") | K19: =1-AVERAGEIFS('Availability Report - NGL'!P:P,'Availability Report - NGL'!$G:$G,'Billability Summary '!$B19,'Availability Report - NGL'!$D:$D,"Active") | L19: =1-AVERAGEIFS('Availability Report - NGL'!Q:Q,'Availability Report - NGL'!$G:$G,'Billability Summary '!$B19,'Availability Report - NGL'!$D:$D,"Active") | M19: =1-AVERAGEIFS('Availability Report - NGL'!R:R,'Availability Report - NGL'!$G:$G,'Billability Summary '!$B19,'Availability Report - NGL'!$D:$D,"Active") | N19: =1-AVERAGEIFS('Availability Report - NGL'!S:S,'Availability Report - NGL'!$G:$G,'Billability Summary '!$B19,'Availability Report - NGL'!$D:$D,"Active") | O19: =1-AVERAGEIFS('Availability Report - NGL'!T:T,'Availability Report - NGL'!$G:$G,'Billability Summary '!$B19,'Availability Report - NGL'!$D:$D,"Active") | Q19: =AVERAGE(N19:O19) | R19: =1-Q19 | T19: =+SUMIFS('Availability Report - NGL'!#REF!,'Availability Report - NGL'!$G:$G,'Billability Summary '!$B19,'Availability Report - NGL'!$D:$D,"Active") | V19: =+SUMIFS('Availability Report - NGL'!#REF!,'Availability Report - NGL'!$G:$G,'Billability Summary '!$B19,'Availability Report - NGL'!$D:$D,"Active")
B20: Data & AI | C20: =COUNTIFS('Availability Report - NGL'!$G:$G,'Billability Summary '!$B20,'Availability Report - NGL'!$D:$D,"Active") | D20: =1-AVERAGEIFS('Availability Report - NGL'!I:I,'Availability Report - NGL'!$G:$G,'Billability Summary '!$B20,'Availability Report - NGL'!$D:$D,"Active") | E20: =1-AVERAGEIFS('Availability Report - NGL'!J:J,'Availability Report - NGL'!$G:$G,'Billability Summary '!$B20,'Availability Report - NGL'!$D:$D,"Active") | F20: =1-AVERAGEIFS('Availability Report - NGL'!K:K,'Availability Report - NGL'!$G:$G,'Billability Summary '!$B20,'Availability Report - NGL'!$D:$D,"Active") | G20: =1-AVERAGEIFS('Availability Report - NGL'!L:L,'Availability Report - NGL'!$G:$G,'Billability Summary '!$B20,'Availability Report - NGL'!$D:$D,"Active") | H20: =1-AVERAGEIFS('Availability Report - NGL'!M:M,'Availability Report - NGL'!$G:$G,'Billability Summary '!$B20,'Availability Report - NGL'!$D:$D,"Active") | I20: =1-AVERAGEIFS('Availability Report - NGL'!N:N,'Availability Report - NGL'!$G:$G,'Billability Summary '!$B20,'Availability Report - NGL'!$D:$D,"Active") | J20: =1-AVERAGEIFS('Availability Report - NGL'!O:O,'Availability Report - NGL'!$G:$G,'Billability Summary '!$B20,'Availability Report - NGL'!$D:$D,"Active") | K20: =1-AVERAGEIFS('Availability Report - NGL'!P:P,'Availability Report - NGL'!$G:$G,'Billability Summary '!$B20,'Availability Report - NGL'!$D:$D,"Active") | L20: =1-AVERAGEIFS('Availability Report - NGL'!Q:Q,'Availability Report - NGL'!$G:$G,'Billability Summary '!$B20,'Availability Report - NGL'!$D:$D,"Active") | M20: =1-AVERAGEIFS('Availability Report - NGL'!R:R,'Availability Report - NGL'!$G:$G,'Billability Summary '!$B20,'Availability Report - NGL'!$D:$D,"Active") | N20: =1-AVERAGEIFS('Availability Report - NGL'!S:S,'Availability Report - NGL'!$G:$G,'Billability Summary '!$B20,'Availability Report - NGL'!$D:$D,"Active") | O20: =1-AVERAGEIFS('Availability Report - NGL'!T:T,'Availability Report - NGL'!$G:$G,'Billability Summary '!$B20,'Availability Report - NGL'!$D:$D,"Active") | Q20: =AVERAGE(N20:O20) | R20: =1-Q20 | T20: =+SUMIFS('Availability Report - NGL'!#REF!,'Availability Report - NGL'!$G:$G,'Billability Summary '!$B20,'Availability Report - NGL'!$D:$D,"Active") | V20: =+SUMIFS('Availability Report - NGL'!#REF!,'Availability Report - NGL'!$G:$G,'Billability Summary '!$B20,'Availability Report - NGL'!$D:$D,"Active")
B21: Renewable and Engineering | C21: =COUNTIFS('Availability Report - NGL'!$G:$G,'Billability Summary '!$B21,'Availability Report - NGL'!$D:$D,"Active") | D21: =1-AVERAGEIFS('Availability Report - NGL'!I:I,'Availability Report - NGL'!$G:$G,'Billability Summary '!$B21,'Availability Report - NGL'!$D:$D,"Active") | E21: =1-AVERAGEIFS('Availability Report - NGL'!J:J,'Availability Report - NGL'!$G:$G,'Billability Summary '!$B21,'Availability Report - NGL'!$D:$D,"Active") | F21: =1-AVERAGEIFS('Availability Report - NGL'!K:K,'Availability Report - NGL'!$G:$G,'Billability Summary '!$B21,'Availability Report - NGL'!$D:$D,"Active") | G21: =1-AVERAGEIFS('Availability Report - NGL'!L:L,'Availability Report - NGL'!$G:$G,'Billability Summary '!$B21,'Availability Report - NGL'!$D:$D,"Active") | H21: =1-AVERAGEIFS('Availability Report - NGL'!M:M,'Availability Report - NGL'!$G:$G,'Billability Summary '!$B21,'Availability Report - NGL'!$D:$D,"Active") | I21: =1-AVERAGEIFS('Availability Report - NGL'!N:N,'Availability Report - NGL'!$G:$G,'Billability Summary '!$B21,'Availability Report - NGL'!$D:$D,"Active") | J21: =1-AVERAGEIFS('Availability Report - NGL'!O:O,'Availability Report - NGL'!$G:$G,'Billability Summary '!$B21,'Availability Report - NGL'!$D:$D,"Active") | K21: =1-AVERAGEIFS('Availability Report - NGL'!P:P,'Availability Report - NGL'!$G:$G,'Billability Summary '!$B21,'Availability Report - NGL'!$D:$D,"Active") | L21: =1-AVERAGEIFS('Availability Report - NGL'!Q:Q,'Availability Report - NGL'!$G:$G,'Billability Summary '!$B21,'Availability Report - NGL'!$D:$D,"Active") | M21: =1-AVERAGEIFS('Availability Report - NGL'!R:R,'Availability Report - NGL'!$G:$G,'Billability Summary '!$B21,'Availability Report - NGL'!$D:$D,"Active") | N21: =1-AVERAGEIFS('Availability Report - NGL'!S:S,'Availability Report - NGL'!$G:$G,'Billability Summary '!$B21,'Availability Report - NGL'!$D:$D,"Active") | O21: =1-AVERAGEIFS('Availability Report - NGL'!T:T,'Availability Report - NGL'!$G:$G,'Billability Summary '!$B21,'Availability Report - NGL'!$D:$D,"Active") | Q21: =AVERAGE(N21:O21) | R21: =1-Q21 | T21: =+SUMIFS('Availability Report - NGL'!#REF!,'Availability Report - NGL'!$G:$G,'Billability Summary '!$B21,'Availability Report - NGL'!$D:$D,"Active") | V21: =+SUMIFS('Availability Report - NGL'!#REF!,'Availability Report - NGL'!$G:$G,'Billability Summary '!$B21,'Availability Report - NGL'!$D:$D,"Active")
B22: Growth | C22: =COUNTIFS('Availability Report - NGL'!$G:$G,'Billability Summary '!$B22,'Availability Report - NGL'!$D:$D,"Active") | D22: =1-AVERAGEIFS('Availability Report - NGL'!I:I,'Availability Report - NGL'!$G:$G,'Billability Summary '!$B22,'Availability Report - NGL'!$D:$D,"Active") | E22: =1-AVERAGEIFS('Availability Report - NGL'!J:J,'Availability Report - NGL'!$G:$G,'Billability Summary '!$B22,'Availability Report - NGL'!$D:$D,"Active") | F22: =1-AVERAGEIFS('Availability Report - NGL'!K:K,'Availability Report - NGL'!$G:$G,'Billability Summary '!$B22,'Availability Report - NGL'!$D:$D,"Active") | G22: =1-AVERAGEIFS('Availability Report - NGL'!L:L,'Availability Report - NGL'!$G:$G,'Billability Summary '!$B22,'Availability Report - NGL'!$D:$D,"Active") | H22: =1-AVERAGEIFS('Availability Report - NGL'!M:M,'Availability Report - NGL'!$G:$G,'Billability Summary '!$B22,'Availability Report - NGL'!$D:$D,"Active") | I22: =1-AVERAGEIFS('Availability Report - NGL'!N:N,'Availability Report - NGL'!$G:$G,'Billability Summary '!$B22,'Availability Report - NGL'!$D:$D,"Active") | J22: =1-AVERAGEIFS('Availability Report - NGL'!O:O,'Availability Report - NGL'!$G:$G,'Billability Summary '!$B22,'Availability Report - NGL'!$D:$D,"Active") | K22: =1-AVERAGEIFS('Availability Report - NGL'!P:P,'Availability Report - NGL'!$G:$G,'Billability Summary '!$B22,'Availability Report - NGL'!$D:$D,"Active") | L22: =1-AVERAGEIFS('Availability Report - NGL'!Q:Q,'Availability Report - NGL'!$G:$G,'Billability Summary '!$B22,'Availability Report - NGL'!$D:$D,"Active") | M22: =1-AVERAGEIFS('Availability Report - NGL'!R:R,'Availability Report - NGL'!$G:$G,'Billability Summary '!$B22,'Availability Report - NGL'!$D:$D,"Active") | N22: =1-AVERAGEIFS('Availability Report - NGL'!S:S,'Availability Report - NGL'!$G:$G,'Billability Summary '!$B22,'Availability Report - NGL'!$D:$D,"Active") | O22: =1-AVERAGEIFS('Availability Report - NGL'!T:T,'Availability Report - NGL'!$G:$G,'Billability Summary '!$B22,'Availability Report - NGL'!$D:$D,"Active") | Q22: =AVERAGE(N22:O22) | R22: =1-Q22 | T22: =+SUMIFS('Availability Report - NGL'!#REF!,'Availability Report - NGL'!$G:$G,'Billability Summary '!$B22,'Availability Report - NGL'!$D:$D,"Active") | V22: =+SUMIFS('Availability Report - NGL'!#REF!,'Availability Report - NGL'!$G:$G,'Billability Summary '!$B22,'Availability Report - NGL'!$D:$D,"Active")
B23: GCC - Hyderabad | C23: =COUNTIFS('Availability Report - NGL'!$G:$G,'Billability Summary '!$B23,'Availability Report - NGL'!$D:$D,"Active") | D23: =1-AVERAGEIFS('Availability Report - NGL'!I:I,'Availability Report - NGL'!$G:$G,'Billability Summary '!$B23,'Availability Report - NGL'!$D:$D,"Active") | E23: =1-AVERAGEIFS('Availability Report - NGL'!J:J,'Availability Report - NGL'!$G:$G,'Billability Summary '!$B23,'Availability Report - NGL'!$D:$D,"Active") | F23: =1-AVERAGEIFS('Availability Report - NGL'!K:K,'Availability Report - NGL'!$G:$G,'Billability Summary '!$B23,'Availability Report - NGL'!$D:$D,"Active") | G23: =1-AVERAGEIFS('Availability Report - NGL'!L:L,'Availability Report - NGL'!$G:$G,'Billability Summary '!$B23,'Availability Report - NGL'!$D:$D,"Active") | H23: =1-AVERAGEIFS('Availability Report - NGL'!M:M,'Availability Report - NGL'!$G:$G,'Billability Summary '!$B23,'Availability Report - NGL'!$D:$D,"Active") | I23: =1-AVERAGEIFS('Availability Report - NGL'!N:N,'Availability Report - NGL'!$G:$G,'Billability Summary '!$B23,'Availability Report - NGL'!$D:$D,"Active") | J23: =1-AVERAGEIFS('Availability Report - NGL'!O:O,'Availability Report - NGL'!$G:$G,'Billability Summary '!$B23,'Availability Report - NGL'!$D:$D,"Active") | K23: =1-AVERAGEIFS('Availability Report - NGL'!P:P,'Availability Report - NGL'!$G:$G,'Billability Summary '!$B23,'Availability Report - NGL'!$D:$D,"Active") | L23: =1-AVERAGEIFS('Availability Report - NGL'!Q:Q,'Availability Report - NGL'!$G:$G,'Billability Summary '!$B23,'Availability Report - NGL'!$D:$D,"Active") | M23: =1-AVERAGEIFS('Availability Report - NGL'!R:R,'Availability Report - NGL'!$G:$G,'Billability Summary '!$B23,'Availability Report - NGL'!$D:$D,"Active") | N23: =1-AVERAGEIFS('Availability Report - NGL'!S:S,'Availability Report - NGL'!$G:$G,'Billability Summary '!$B23,'Availability Report - NGL'!$D:$D,"Active") | O23: =1-AVERAGEIFS('Availability Report - NGL'!T:T,'Availability Report - NGL'!$G:$G,'Billability Summary '!$B23,'Availability Report - NGL'!$D:$D,"Active") | Q23: =AVERAGE(N23:O23) | R23: =1-Q23 | T23: =+SUMIFS('Availability Report - NGL'!#REF!,'Availability Report - NGL'!$G:$G,'Billability Summary '!$B23,'Availability Report - NGL'!$D:$D,"Active") | V23: =+SUMIFS('Availability Report - NGL'!#REF!,'Availability Report - NGL'!$G:$G,'Billability Summary '!$B23,'Availability Report - NGL'!$D:$D,"Active")
B24: Strategic Delivery | C24: =COUNTIFS('Availability Report - NGL'!$G:$G,'Billability Summary '!$B24,'Availability Report - NGL'!$D:$D,"Active") | D24: =1-AVERAGEIFS('Availability Report - NGL'!I:I,'Availability Report - NGL'!$G:$G,'Billability Summary '!$B24,'Availability Report - NGL'!$D:$D,"Active") | E24: =1-AVERAGEIFS('Availability Report - NGL'!J:J,'Availability Report - NGL'!$G:$G,'Billability Summary '!$B24,'Availability Report - NGL'!$D:$D,"Active") | F24: =1-AVERAGEIFS('Availability Report - NGL'!K:K,'Availability Report - NGL'!$G:$G,'Billability Summary '!$B24,'Availability Report - NGL'!$D:$D,"Active") | G24: =1-AVERAGEIFS('Availability Report - NGL'!L:L,'Availability Report - NGL'!$G:$G,'Billability Summary '!$B24,'Availability Report - NGL'!$D:$D,"Active") | H24: =1-AVERAGEIFS('Availability Report - NGL'!M:M,'Availability Report - NGL'!$G:$G,'Billability Summary '!$B24,'Availability Report - NGL'!$D:$D,"Active") | I24: =1-AVERAGEIFS('Availability Report - NGL'!N:N,'Availability Report - NGL'!$G:$G,'Billability Summary '!$B24,'Availability Report - NGL'!$D:$D,"Active") | J24: =1-AVERAGEIFS('Availability Report - NGL'!O:O,'Availability Report - NGL'!$G:$G,'Billability Summary '!$B24,'Availability Report - NGL'!$D:$D,"Active") | K24: =1-AVERAGEIFS('Availability Report - NGL'!P:P,'Availability Report - NGL'!$G:$G,'Billability Summary '!$B24,'Availability Report - NGL'!$D:$D,"Active") | L24: =1-AVERAGEIFS('Availability Report - NGL'!Q:Q,'Availability Report - NGL'!$G:$G,'Billability Summary '!$B24,'Availability Report - NGL'!$D:$D,"Active") | M24: =1-AVERAGEIFS('Availability Report - NGL'!R:R,'Availability Report - NGL'!$G:$G,'Billability Summary '!$B24,'Availability Report - NGL'!$D:$D,"Active") | N24: =1-AVERAGEIFS('Availability Report - NGL'!S:S,'Availability Report - NGL'!$G:$G,'Billability Summary '!$B24,'Availability Report - NGL'!$D:$D,"Active") | O24: =1-AVERAGEIFS('Availability Report - NGL'!T:T,'Availability Report - NGL'!$G:$G,'Billability Summary '!$B24,'Availability Report - NGL'!$D:$D,"Active") | Q24: =AVERAGE(N24:O24) | R24: =1-Q24 | T24: =+SUMIFS('Availability Report - NGL'!#REF!,'Availability Report - NGL'!$G:$G,'Billability Summary '!$B24,'Availability Report - NGL'!$D:$D,"Active") | V24: =+SUMIFS('Availability Report - NGL'!#REF!,'Availability Report - NGL'!$G:$G,'Billability Summary '!$B24,'Availability Report - NGL'!$D:$D,"Active")
C25: =SUM(C18:C24) | T25: =SUM(T18:T24) | V25: =SUM(V18:V24)
Q26: Mar'26
B27: Sub Practice | C27: Active Resources | D27: 45748 | E27: 45778 | F27: 45809 | G27: 45839 | H27: 45870 | I27: 45901 | J27: 45931 | K27: 45962 | L27: 45992 | M27: 46023 | N27: 46054 | O27: 46082 | Q27: Avg Billability | R27: Avg Availability | T27: Non Billable cost from April'25 to March '26 | V27: Non Billable cost from Jan'26 to March '26
B28: OT | C28: =COUNTIFS('Availability Report - NGL'!$H:$H,'Billability Summary '!$B28,'Availability Report - NGL'!$D:$D,"Active") | D28: =IFERROR(1-AVERAGEIFS('Availability Report - NGL'!I:I,'Availability Report - NGL'!$H:$H,'Billability Summary '!$B28,'Availability Report - NGL'!$D:$D,"Active"),0) | E28: =IFERROR(1-AVERAGEIFS('Availability Report - NGL'!J:J,'Availability Report - NGL'!$H:$H,'Billability Summary '!$B28,'Availability Report - NGL'!$D:$D,"Active"),0) | F28: =IFERROR(1-AVERAGEIFS('Availability Report - NGL'!K:K,'Availability Report - NGL'!$H:$H,'Billability Summary '!$B28,'Availability Report - NGL'!$D:$D,"Active"),0) | G28: =IFERROR(1-AVERAGEIFS('Availability Report - NGL'!L:L,'Availability Report - NGL'!$H:$H,'Billability Summary '!$B28,'Availability Report - NGL'!$D:$D,"Active"),0) | H28: =IFERROR(1-AVERAGEIFS('Availability Report - NGL'!M:M,'Availability Report - NGL'!$H:$H,'Billability Summary '!$B28,'Availability Report - NGL'!$D:$D,"Active"),0) | I28: =IFERROR(1-AVERAGEIFS('Availability Report - NGL'!N:N,'Availability Report - NGL'!$H:$H,'Billability Summary '!$B28,'Availability Report - NGL'!$D:$D,"Active"),0) | J28: =IFERROR(1-AVERAGEIFS('Availability Report - NGL'!O:O,'Availability Report - NGL'!$H:$H,'Billability Summary '!$B28,'Availability Report - NGL'!$D:$D,"Active"),0) | K28: =IFERROR(1-AVERAGEIFS('Availability Report - NGL'!P:P,'Availability Report - NGL'!$H:$H,'Billability Summary '!$B28,'Availability Report - NGL'!$D:$D,"Active"),0) | L28: =IFERROR(1-AVERAGEIFS('Availability Report - NGL'!Q:Q,'Availability Report - NGL'!$H:$H,'Billability Summary '!$B28,'Availability Report - NGL'!$D:$D,"Active"),0) | M28: =IFERROR(1-AVERAGEIFS('Availability Report - NGL'!R:R,'Availability Report - NGL'!$H:$H,'Billability Summary '!$B28,'Availability Report - NGL'!$D:$D,"Active"),0) | N28: =IFERROR(1-AVERAGEIFS('Availability Report - NGL'!S:S,'Availability Report - NGL'!$H:$H,'Billability Summary '!$B28,'Availability Report - NGL'!$D:$D,"Active"),0) | O28: =IFERROR(1-AVERAGEIFS('Availability Report - NGL'!T:T,'Availability Report - NGL'!$H:$H,'Billability Summary '!$B28,'Availability Report - NGL'!$D:$D,"Active"),0) | Q28: =AVERAGE(N28:O28) | R28: =1-Q28 | T28: =+SUMIFS('Availability Report - NGL'!#REF!,'Availability Report - NGL'!$H:$H,'Billability Summary '!$B28,'Availability Report - NGL'!$D:$D,"Active") | V28: =+SUMIFS('Availability Report - NGL'!#REF!,'Availability Report - NGL'!$H:$H,'Billability Summary '!$B28,'Availability Report - NGL'!$D:$D,"Active")
B29: Digital Solutions | C29: =COUNTIFS('Availability Report - NGL'!$H:$H,'Billability Summary '!$B29,'Availability Report - NGL'!$D:$D,"Active") | D29: =IFERROR(1-AVERAGEIFS('Availability Report - NGL'!I:I,'Availability Report - NGL'!$H:$H,'Billability Summary '!$B29,'Availability Report - NGL'!$D:$D,"Active"),0) | E29: =IFERROR(1-AVERAGEIFS('Availability Report - NGL'!J:J,'Availability Report - NGL'!$H:$H,'Billability Summary '!$B29,'Availability Report - NGL'!$D:$D,"Active"),0) | F29: =IFERROR(1-AVERAGEIFS('Availability Report - NGL'!K:K,'Availability Report - NGL'!$H:$H,'Billability Summary '!$B29,'Availability Report - NGL'!$D:$D,"Active"),0) | G29: =IFERROR(1-AVERAGEIFS('Availability Report - NGL'!L:L,'Availability Report - NGL'!$H:$H,'Billability Summary '!$B29,'Availability Report - NGL'!$D:$D,"Active"),0) | H29: =IFERROR(1-AVERAGEIFS('Availability Report - NGL'!M:M,'Availability Report - NGL'!$H:$H,'Billability Summary '!$B29,'Availability Report - NGL'!$D:$D,"Active"),0) | I29: =IFERROR(1-AVERAGEIFS('Availability Report - NGL'!N:N,'Availability Report - NGL'!$H:$H,'Billability Summary '!$B29,'Availability Report - NGL'!$D:$D,"Active"),0) | J29: =IFERROR(1-AVERAGEIFS('Availability Report - NGL'!O:O,'Availability Report - NGL'!$H:$H,'Billability Summary '!$B29,'Availability Report - NGL'!$D:$D,"Active"),0) | K29: =IFERROR(1-AVERAGEIFS('Availability Report - NGL'!P:P,'Availability Report - NGL'!$H:$H,'Billability Summary '!$B29,'Availability Report - NGL'!$D:$D,"Active"),0) | L29: =IFERROR(1-AVERAGEIFS('Availability Report - NGL'!Q:Q,'Availability Report - NGL'!$H:$H,'Billability Summary '!$B29,'Availability Report - NGL'!$D:$D,"Active"),0) | M29: =IFERROR(1-AVERAGEIFS('Availability Report - NGL'!R:R,'Availability Report - NGL'!$H:$H,'Billability Summary '!$B29,'Availability Report - NGL'!$D:$D,"Active"),0) | N29: =IFERROR(1-AVERAGEIFS('Availability Report - NGL'!S:S,'Availability Report - NGL'!$H:$H,'Billability Summary '!$B29,'Availability Report - NGL'!$D:$D,"Active"),0) | O29: =IFERROR(1-AVERAGEIFS('Availability Report - NGL'!T:T,'Availability Report - NGL'!$H:$H,'Billability Summary '!$B29,'Availability Report - NGL'!$D:$D,"Active"),0) | Q29: =AVERAGE(N29:O29) | R29: =1-Q29 | T29: =+SUMIFS('Availability Report - NGL'!#REF!,'Availability Report - NGL'!$H:$H,'Billability Summary '!$B29,'Availability Report - NGL'!$D:$D,"Active") | V29: =+SUMIFS('Availability Report - NGL'!#REF!,'Availability Report - NGL'!$H:$H,'Billability Summary '!$B29,'Availability Report - NGL'!$D:$D,"Active")
B30: Platform Engineering | C30: =COUNTIFS('Availability Report - NGL'!$H:$H,'Billability Summary '!$B30,'Availability Report - NGL'!$D:$D,"Active") | D30: =IFERROR(1-AVERAGEIFS('Availability Report - NGL'!I:I,'Availability Report - NGL'!$H:$H,'Billability Summary '!$B30,'Availability Report - NGL'!$D:$D,"Active"),0) | E30: =IFERROR(1-AVERAGEIFS('Availability Report - NGL'!J:J,'Availability Report - NGL'!$H:$H,'Billability Summary '!$B30,'Availability Report - NGL'!$D:$D,"Active"),0) | F30: =IFERROR(1-AVERAGEIFS('Availability Report - NGL'!K:K,'Availability Report - NGL'!$H:$H,'Billability Summary '!$B30,'Availability Report - NGL'!$D:$D,"Active"),0) | G30: =IFERROR(1-AVERAGEIFS('Availability Report - NGL'!L:L,'Availability Report - NGL'!$H:$H,'Billability Summary '!$B30,'Availability Report - NGL'!$D:$D,"Active"),0) | H30: =IFERROR(1-AVERAGEIFS('Availability Report - NGL'!M:M,'Availability Report - NGL'!$H:$H,'Billability Summary '!$B30,'Availability Report - NGL'!$D:$D,"Active"),0) | I30: =IFERROR(1-AVERAGEIFS('Availability Report - NGL'!N:N,'Availability Report - NGL'!$H:$H,'Billability Summary '!$B30,'Availability Report - NGL'!$D:$D,"Active"),0) | J30: =IFERROR(1-AVERAGEIFS('Availability Report - NGL'!O:O,'Availability Report - NGL'!$H:$H,'Billability Summary '!$B30,'Availability Report - NGL'!$D:$D,"Active"),0) | K30: =IFERROR(1-AVERAGEIFS('Availability Report - NGL'!P:P,'Availability Report - NGL'!$H:$H,'Billability Summary '!$B30,'Availability Report - NGL'!$D:$D,"Active"),0) | L30: =IFERROR(1-AVERAGEIFS('Availability Report - NGL'!Q:Q,'Availability Report - NGL'!$H:$H,'Billability Summary '!$B30,'Availability Report - NGL'!$D:$D,"Active"),0) | M30: =IFERROR(1-AVERAGEIFS('Availability Report - NGL'!R:R,'Availability Report - NGL'!$H:$H,'Billability Summary '!$B30,'Availability Report - NGL'!$D:$D,"Active"),0) | N30: =IFERROR(1-AVERAGEIFS('Availability Report - NGL'!S:S,'Availability Report - NGL'!$H:$H,'Billability Summary '!$B30,'Availability Report - NGL'!$D:$D,"Active"),0) | O30: =IFERROR(1-AVERAGEIFS('Availability Report - NGL'!T:T,'Availability Report - NGL'!$H:$H,'Billability Summary '!$B30,'Availability Report - NGL'!$D:$D,"Active"),0) | Q30: =AVERAGE(N30:O30) | R30: =1-Q30 | T30: =+SUMIFS('Availability Report - NGL'!#REF!,'Availability Report - NGL'!$H:$H,'Billability Summary '!$B30,'Availability Report - NGL'!$D:$D,"Active") | V30: =+SUMIFS('Availability Report - NGL'!#REF!,'Availability Report - NGL'!$H:$H,'Billability Summary '!$B30,'Availability Report - NGL'!$D:$D,"Active")
B31: Project & Buiness Analysis | C31: =COUNTIFS('Availability Report - NGL'!$H:$H,'Billability Summary '!$B31,'Availability Report - NGL'!$D:$D,"Active") | D31: =IFERROR(1-AVERAGEIFS('Availability Report - NGL'!I:I,'Availability Report - NGL'!$H:$H,'Billability Summary '!$B31,'Availability Report - NGL'!$D:$D,"Active"),0) | E31: =IFERROR(1-AVERAGEIFS('Availability Report - NGL'!J:J,'Availability Report - NGL'!$H:$H,'Billability Summary '!$B31,'Availability Report - NGL'!$D:$D,"Active"),0) | F31: =IFERROR(1-AVERAGEIFS('Availability Report - NGL'!K:K,'Availability Report - NGL'!$H:$H,'Billability Summary '!$B31,'Availability Report - NGL'!$D:$D,"Active"),0) | G31: =IFERROR(1-AVERAGEIFS('Availability Report - NGL'!L:L,'Availability Report - NGL'!$H:$H,'Billability Summary '!$B31,'Availability Report - NGL'!$D:$D,"Active"),0) | H31: =IFERROR(1-AVERAGEIFS('Availability Report - NGL'!M:M,'Availability Report - NGL'!$H:$H,'Billability Summary '!$B31,'Availability Report - NGL'!$D:$D,"Active"),0) | I31: =IFERROR(1-AVERAGEIFS('Availability Report - NGL'!N:N,'Availability Report - NGL'!$H:$H,'Billability Summary '!$B31,'Availability Report - NGL'!$D:$D,"Active"),0) | J31: =IFERROR(1-AVERAGEIFS('Availability Report - NGL'!O:O,'Availability Report - NGL'!$H:$H,'Billability Summary '!$B31,'Availability Report - NGL'!$D:$D,"Active"),0) | K31: =IFERROR(1-AVERAGEIFS('Availability Report - NGL'!P:P,'Availability Report - NGL'!$H:$H,'Billability Summary '!$B31,'Availability Report - NGL'!$D:$D,"Active"),0) | L31: =IFERROR(1-AVERAGEIFS('Availability Report - NGL'!Q:Q,'Availability Report - NGL'!$H:$H,'Billability Summary '!$B31,'Availability Report - NGL'!$D:$D,"Active"),0) | M31: =IFERROR(1-AVERAGEIFS('Availability Report - NGL'!R:R,'Availability Report - NGL'!$H:$H,'Billability Summary '!$B31,'Availability Report - NGL'!$D:$D,"Active"),0) | N31: =IFERROR(1-AVERAGEIFS('Availability Report - NGL'!S:S,'Availability Report - NGL'!$H:$H,'Billability Summary '!$B31,'Availability Report - NGL'!$D:$D,"Active"),0) | O31: =IFERROR(1-AVERAGEIFS('Availability Report - NGL'!T:T,'Availability Report - NGL'!$H:$H,'Billability Summary '!$B31,'Availability Report - NGL'!$D:$D,"Active"),0) | Q31: =AVERAGE(N31:O31) | R31: =1-Q31 | T31: =+SUMIFS('Availability Report - NGL'!#REF!,'Availability Report - NGL'!$H:$H,'Billability Summary '!$B31,'Availability Report - NGL'!$D:$D,"Active") | V31: =+SUMIFS('Availability Report - NGL'!#REF!,'Availability Report - NGL'!$H:$H,'Billability Summary '!$B31,'Availability Report - NGL'!$D:$D,"Active")
B32: AI and Analytics | C32: =COUNTIFS('Availability Report - NGL'!$H:$H,'Billability Summary '!$B32,'Availability Report - NGL'!$D:$D,"Active") | D32: =IFERROR(1-AVERAGEIFS('Availability Report - NGL'!I:I,'Availability Report - NGL'!$H:$H,'Billability Summary '!$B32,'Availability Report - NGL'!$D:$D,"Active"),0) | E32: =IFERROR(1-AVERAGEIFS('Availability Report - NGL'!J:J,'Availability Report - NGL'!$H:$H,'Billability Summary '!$B32,'Availability Report - NGL'!$D:$D,"Active"),0) | F32: =IFERROR(1-AVERAGEIFS('Availability Report - NGL'!K:K,'Availability Report - NGL'!$H:$H,'Billability Summary '!$B32,'Availability Report - NGL'!$D:$D,"Active"),0) | G32: =IFERROR(1-AVERAGEIFS('Availability Report - NGL'!L:L,'Availability Report - NGL'!$H:$H,'Billability Summary '!$B32,'Availability Report - NGL'!$D:$D,"Active"),0) | H32: =IFERROR(1-AVERAGEIFS('Availability Report - NGL'!M:M,'Availability Report - NGL'!$H:$H,'Billability Summary '!$B32,'Availability Report - NGL'!$D:$D,"Active"),0) | I32: =IFERROR(1-AVERAGEIFS('Availability Report - NGL'!N:N,'Availability Report - NGL'!$H:$H,'Billability Summary '!$B32,'Availability Report - NGL'!$D:$D,"Active"),0) | J32: =IFERROR(1-AVERAGEIFS('Availability Report - NGL'!O:O,'Availability Report - NGL'!$H:$H,'Billability Summary '!$B32,'Availability Report - NGL'!$D:$D,"Active"),0) | K32: =IFERROR(1-AVERAGEIFS('Availability Report - NGL'!P:P,'Availability Report - NGL'!$H:$H,'Billability Summary '!$B32,'Availability Report - NGL'!$D:$D,"Active"),0) | L32: =IFERROR(1-AVERAGEIFS('Availability Report - NGL'!Q:Q,'Availability Report - NGL'!$H:$H,'Billability Summary '!$B32,'Availability Report - NGL'!$D:$D,"Active"),0) | M32: =IFERROR(1-AVERAGEIFS('Availability Report - NGL'!R:R,'Availability Report - NGL'!$H:$H,'Billability Summary '!$B32,'Availability Report - NGL'!$D:$D,"Active"),0) | N32: =IFERROR(1-AVERAGEIFS('Availability Report - NGL'!S:S,'Availability Report - NGL'!$H:$H,'Billability Summary '!$B32,'Availability Report - NGL'!$D:$D,"Active"),0) | O32: =IFERROR(1-AVERAGEIFS('Availability Report - NGL'!T:T,'Availability Report - NGL'!$H:$H,'Billability Summary '!$B32,'Availability Report - NGL'!$D:$D,"Active"),0) | Q32: =AVERAGE(N32:O32) | R32: =1-Q32 | T32: =+SUMIFS('Availability Report - NGL'!#REF!,'Availability Report - NGL'!$H:$H,'Billability Summary '!$B32,'Availability Report - NGL'!$D:$D,"Active") | V32: =+SUMIFS('Availability Report - NGL'!#REF!,'Availability Report - NGL'!$H:$H,'Billability Summary '!$B32,'Availability Report - NGL'!$D:$D,"Active")
B33: Renewable Advisory | C33: =COUNTIFS('Availability Report - NGL'!$H:$H,'Billability Summary '!$B33,'Availability Report - NGL'!$D:$D,"Active") | D33: =IFERROR(1-AVERAGEIFS('Availability Report - NGL'!I:I,'Availability Report - NGL'!$H:$H,'Billability Summary '!$B33,'Availability Report - NGL'!$D:$D,"Active"),0) | E33: =IFERROR(1-AVERAGEIFS('Availability Report - NGL'!J:J,'Availability Report - NGL'!$H:$H,'Billability Summary '!$B33,'Availability Report - NGL'!$D:$D,"Active"),0) | F33: =IFERROR(1-AVERAGEIFS('Availability Report - NGL'!K:K,'Availability Report - NGL'!$H:$H,'Billability Summary '!$B33,'Availability Report - NGL'!$D:$D,"Active"),0) | G33: =IFERROR(1-AVERAGEIFS('Availability Report - NGL'!L:L,'Availability Report - NGL'!$H:$H,'Billability Summary '!$B33,'Availability Report - NGL'!$D:$D,"Active"),0) | H33: =IFERROR(1-AVERAGEIFS('Availability Report - NGL'!M:M,'Availability Report - NGL'!$H:$H,'Billability Summary '!$B33,'Availability Report - NGL'!$D:$D,"Active"),0) | I33: =IFERROR(1-AVERAGEIFS('Availability Report - NGL'!N:N,'Availability Report - NGL'!$H:$H,'Billability Summary '!$B33,'Availability Report - NGL'!$D:$D,"Active"),0) | J33: =IFERROR(1-AVERAGEIFS('Availability Report - NGL'!O:O,'Availability Report - NGL'!$H:$H,'Billability Summary '!$B33,'Availability Report - NGL'!$D:$D,"Active"),0) | K33: =IFERROR(1-AVERAGEIFS('Availability Report - NGL'!P:P,'Availability Report - NGL'!$H:$H,'Billability Summary '!$B33,'Availability Report - NGL'!$D:$D,"Active"),0) | L33: =IFERROR(1-AVERAGEIFS('Availability Report - NGL'!Q:Q,'Availability Report - NGL'!$H:$H,'Billability Summary '!$B33,'Availability Report - NGL'!$D:$D,"Active"),0) | M33: =IFERROR(1-AVERAGEIFS('Availability Report - NGL'!R:R,'Availability Report - NGL'!$H:$H,'Billability Summary '!$B33,'Availability Report - NGL'!$D:$D,"Active"),0) | N33: =IFERROR(1-AVERAGEIFS('Availability Report - NGL'!S:S,'Availability Report - NGL'!$H:$H,'Billability Summary '!$B33,'Availability Report - NGL'!$D:$D,"Active"),0) | O33: =IFERROR(1-AVERAGEIFS('Availability Report - NGL'!T:T,'Availability Report - NGL'!$H:$H,'Billability Summary '!$B33,'Availability Report - NGL'!$D:$D,"Active"),0) | Q33: =AVERAGE(N33:O33) | R33: =1-Q33 | T33: =+SUMIFS('Availability Report - NGL'!#REF!,'Availability Report - NGL'!$H:$H,'Billability Summary '!$B33,'Availability Report - NGL'!$D:$D,"Active") | V33: =+SUMIFS('Availability Report - NGL'!#REF!,'Availability Report - NGL'!$H:$H,'Billability Summary '!$B33,'Availability Report - NGL'!$D:$D,"Active")
B34: SAP | C34: =COUNTIFS('Availability Report - NGL'!$H:$H,'Billability Summary '!$B34,'Availability Report - NGL'!$D:$D,"Active") | D34: =IFERROR(1-AVERAGEIFS('Availability Report - NGL'!I:I,'Availability Report - NGL'!$H:$H,'Billability Summary '!$B34,'Availability Report - NGL'!$D:$D,"Active"),0) | E34: =IFERROR(1-AVERAGEIFS('Availability Report - NGL'!J:J,'Availability Report - NGL'!$H:$H,'Billability Summary '!$B34,'Availability Report - NGL'!$D:$D,"Active"),0) | F34: =IFERROR(1-AVERAGEIFS('Availability Report - NGL'!K:K,'Availability Report - NGL'!$H:$H,'Billability Summary '!$B34,'Availability Report - NGL'!$D:$D,"Active"),0) | G34: =IFERROR(1-AVERAGEIFS('Availability Report - NGL'!L:L,'Availability Report - NGL'!$H:$H,'Billability Summary '!$B34,'Availability Report - NGL'!$D:$D,"Active"),0) | H34: =IFERROR(1-AVERAGEIFS('Availability Report - NGL'!M:M,'Availability Report - NGL'!$H:$H,'Billability Summary '!$B34,'Availability Report - NGL'!$D:$D,"Active"),0) | I34: =IFERROR(1-AVERAGEIFS('Availability Report - NGL'!N:N,'Availability Report - NGL'!$H:$H,'Billability Summary '!$B34,'Availability Report - NGL'!$D:$D,"Active"),0) | J34: =IFERROR(1-AVERAGEIFS('Availability Report - NGL'!O:O,'Availability Report - NGL'!$H:$H,'Billability Summary '!$B34,'Availability Report - NGL'!$D:$D,"Active"),0) | K34: =IFERROR(1-AVERAGEIFS('Availability Report - NGL'!P:P,'Availability Report - NGL'!$H:$H,'Billability Summary '!$B34,'Availability Report - NGL'!$D:$D,"Active"),0) | L34: =IFERROR(1-AVERAGEIFS('Availability Report - NGL'!Q:Q,'Availability Report - NGL'!$H:$H,'Billability Summary '!$B34,'Availability Report - NGL'!$D:$D,"Active"),0) | M34: =IFERROR(1-AVERAGEIFS('Availability Report - NGL'!R:R,'Availability Report - NGL'!$H:$H,'Billability Summary '!$B34,'Availability Report - NGL'!$D:$D,"Active"),0) | N34: =IFERROR(1-AVERAGEIFS('Availability Report - NGL'!S:S,'Availability Report - NGL'!$H:$H,'Billability Summary '!$B34,'Availability Report - NGL'!$D:$D,"Active"),0) | O34: =IFERROR(1-AVERAGEIFS('Availability Report - NGL'!T:T,'Availability Report - NGL'!$H:$H,'Billability Summary '!$B34,'Availability Report - NGL'!$D:$D,"Active"),0) | Q34: =AVERAGE(N34:O34) | R34: =1-Q34 | T34: =+SUMIFS('Availability Report - NGL'!#REF!,'Availability Report - NGL'!$H:$H,'Billability Summary '!$B34,'Availability Report - NGL'!$D:$D,"Active") | V34: =+SUMIFS('Availability Report - NGL'!#REF!,'Availability Report - NGL'!$H:$H,'Billability Summary '!$B34,'Availability Report - NGL'!$D:$D,"Active")
B35: Design Engineering | C35: =COUNTIFS('Availability Report - NGL'!$H:$H,'Billability Summary '!$B35,'Availability Report - NGL'!$D:$D,"Active") | D35: =IFERROR(1-AVERAGEIFS('Availability Report - NGL'!I:I,'Availability Report - NGL'!$H:$H,'Billability Summary '!$B35,'Availability Report - NGL'!$D:$D,"Active"),0) | E35: =IFERROR(1-AVERAGEIFS('Availability Report - NGL'!J:J,'Availability Report - NGL'!$H:$H,'Billability Summary '!$B35,'Availability Report - NGL'!$D:$D,"Active"),0) | F35: =IFERROR(1-AVERAGEIFS('Availability Report - NGL'!K:K,'Availability Report - NGL'!$H:$H,'Billability Summary '!$B35,'Availability Report - NGL'!$D:$D,"Active"),0) | G35: =IFERROR(1-AVERAGEIFS('Availability Report - NGL'!L:L,'Availability Report - NGL'!$H:$H,'Billability Summary '!$B35,'Availability Report - NGL'!$D:$D,"Active"),0) | H35: =IFERROR(1-AVERAGEIFS('Availability Report - NGL'!M:M,'Availability Report - NGL'!$H:$H,'Billability Summary '!$B35,'Availability Report - NGL'!$D:$D,"Active"),0) | I35: =IFERROR(1-AVERAGEIFS('Availability Report - NGL'!N:N,'Availability Report - NGL'!$H:$H,'Billability Summary '!$B35,'Availability Report - NGL'!$D:$D,"Active"),0) | J35: =IFERROR(1-AVERAGEIFS('Availability Report - NGL'!O:O,'Availability Report - NGL'!$H:$H,'Billability Summary '!$B35,'Availability Report - NGL'!$D:$D,"Active"),0) | K35: =IFERROR(1-AVERAGEIFS('Availability Report - NGL'!P:P,'Availability Report - NGL'!$H:$H,'Billability Summary '!$B35,'Availability Report - NGL'!$D:$D,"Active"),0) | L35: =IFERROR(1-AVERAGEIFS('Availability Report - NGL'!Q:Q,'Availability Report - NGL'!$H:$H,'Billability Summary '!$B35,'Availability Report - NGL'!$D:$D,"Active"),0) | M35: =IFERROR(1-AVERAGEIFS('Availability Report - NGL'!R:R,'Availability Report - NGL'!$H:$H,'Billability Summary '!$B35,'Availability Report - NGL'!$D:$D,"Active"),0) | N35: =IFERROR(1-AVERAGEIFS('Availability Report - NGL'!S:S,'Availability Report - NGL'!$H:$H,'Billability Summary '!$B35,'Availability Report - NGL'!$D:$D,"Active"),0) | O35: =IFERROR(1-AVERAGEIFS('Availability Report - NGL'!T:T,'Availability Report - NGL'!$H:$H,'Billability Summary '!$B35,'Availability Report - NGL'!$D:$D,"Active"),0) | Q35: =AVERAGE(N35:O35) | R35: =1-Q35 | T35: =+SUMIFS('Availability Report - NGL'!#REF!,'Availability Report - NGL'!$H:$H,'Billability Summary '!$B35,'Availability Report - NGL'!$D:$D,"Active") | V35: =+SUMIFS('Availability Report - NGL'!#REF!,'Availability Report - NGL'!$H:$H,'Billability Summary '!$B35,'Availability Report - NGL'!$D:$D,"Active")
B36: Growth | C36: =COUNTIFS('Availability Report - NGL'!$H:$H,'Billability Summary '!$B36,'Availability Report - NGL'!$D:$D,"Active") | D36: =IFERROR(1-AVERAGEIFS('Availability Report - NGL'!I:I,'Availability Report - NGL'!$H:$H,'Billability Summary '!$B36,'Availability Report - NGL'!$D:$D,"Active"),0) | E36: =IFERROR(1-AVERAGEIFS('Availability Report - NGL'!J:J,'Availability Report - NGL'!$H:$H,'Billability Summary '!$B36,'Availability Report - NGL'!$D:$D,"Active"),0) | F36: =IFERROR(1-AVERAGEIFS('Availability Report - NGL'!K:K,'Availability Report - NGL'!$H:$H,'Billability Summary '!$B36,'Availability Report - NGL'!$D:$D,"Active"),0) | G36: =IFERROR(1-AVERAGEIFS('Availability Report - NGL'!L:L,'Availability Report - NGL'!$H:$H,'Billability Summary '!$B36,'Availability Report - NGL'!$D:$D,"Active"),0) | H36: =IFERROR(1-AVERAGEIFS('Availability Report - NGL'!M:M,'Availability Report - NGL'!$H:$H,'Billability Summary '!$B36,'Availability Report - NGL'!$D:$D,"Active"),0) | I36: =IFERROR(1-AVERAGEIFS('Availability Report - NGL'!N:N,'Availability Report - NGL'!$H:$H,'Billability Summary '!$B36,'Availability Report - NGL'!$D:$D,"Active"),0) | J36: =IFERROR(1-AVERAGEIFS('Availability Report - NGL'!O:O,'Availability Report - NGL'!$H:$H,'Billability Summary '!$B36,'Availability Report - NGL'!$D:$D,"Active"),0) | K36: =IFERROR(1-AVERAGEIFS('Availability Report - NGL'!P:P,'Availability Report - NGL'!$H:$H,'Billability Summary '!$B36,'Availability Report - NGL'!$D:$D,"Active"),0) | L36: =IFERROR(1-AVERAGEIFS('Availability Report - NGL'!Q:Q,'Availability Report - NGL'!$H:$H,'Billability Summary '!$B36,'Availability Report - NGL'!$D:$D,"Active"),0) | M36: =IFERROR(1-AVERAGEIFS('Availability Report - NGL'!R:R,'Availability Report - NGL'!$H:$H,'Billability Summary '!$B36,'Availability Report - NGL'!$D:$D,"Active"),0) | N36: =IFERROR(1-AVERAGEIFS('Availability Report - NGL'!S:S,'Availability Report - NGL'!$H:$H,'Billability Summary '!$B36,'Availability Report - NGL'!$D:$D,"Active"),0) | O36: =IFERROR(1-AVERAGEIFS('Availability Report - NGL'!T:T,'Availability Report - NGL'!$H:$H,'Billability Summary '!$B36,'Availability Report - NGL'!$D:$D,"Active"),0) | Q36: =AVERAGE(N36:O36) | R36: =1-Q36 | T36: =+SUMIFS('Availability Report - NGL'!#REF!,'Availability Report - NGL'!$H:$H,'Billability Summary '!$B36,'Availability Report - NGL'!$D:$D,"Active") | V36: =+SUMIFS('Availability Report - NGL'!#REF!,'Availability Report - NGL'!$H:$H,'Billability Summary '!$B36,'Availability Report - NGL'!$D:$D,"Active")
B37: Managed Services | C37: =COUNTIFS('Availability Report - NGL'!$H:$H,'Billability Summary '!$B37,'Availability Report - NGL'!$D:$D,"Active") | D37: =IFERROR(1-AVERAGEIFS('Availability Report - NGL'!I:I,'Availability Report - NGL'!$H:$H,'Billability Summary '!$B37,'Availability Report - NGL'!$D:$D,"Active"),0) | E37: =IFERROR(1-AVERAGEIFS('Availability Report - NGL'!J:J,'Availability Report - NGL'!$H:$H,'Billability Summary '!$B37,'Availability Report - NGL'!$D:$D,"Active"),0) | F37: =IFERROR(1-AVERAGEIFS('Availability Report - NGL'!K:K,'Availability Report - NGL'!$H:$H,'Billability Summary '!$B37,'Availability Report - NGL'!$D:$D,"Active"),0) | G37: =IFERROR(1-AVERAGEIFS('Availability Report - NGL'!L:L,'Availability Report - NGL'!$H:$H,'Billability Summary '!$B37,'Availability Report - NGL'!$D:$D,"Active"),0) | H37: =IFERROR(1-AVERAGEIFS('Availability Report - NGL'!M:M,'Availability Report - NGL'!$H:$H,'Billability Summary '!$B37,'Availability Report - NGL'!$D:$D,"Active"),0) | I37: =IFERROR(1-AVERAGEIFS('Availability Report - NGL'!N:N,'Availability Report - NGL'!$H:$H,'Billability Summary '!$B37,'Availability Report - NGL'!$D:$D,"Active"),0) | J37: =IFERROR(1-AVERAGEIFS('Availability Report - NGL'!O:O,'Availability Report - NGL'!$H:$H,'Billability Summary '!$B37,'Availability Report - NGL'!$D:$D,"Active"),0) | K37: =IFERROR(1-AVERAGEIFS('Availability Report - NGL'!P:P,'Availability Report - NGL'!$H:$H,'Billability Summary '!$B37,'Availability Report - NGL'!$D:$D,"Active"),0) | L37: =IFERROR(1-AVERAGEIFS('Availability Report - NGL'!Q:Q,'Availability Report - NGL'!$H:$H,'Billability Summary '!$B37,'Availability Report - NGL'!$D:$D,"Active"),0) | M37: =IFERROR(1-AVERAGEIFS('Availability Report - NGL'!R:R,'Availability Report - NGL'!$H:$H,'Billability Summary '!$B37,'Availability Report - NGL'!$D:$D,"Active"),0) | N37: =IFERROR(1-AVERAGEIFS('Availability Report - NGL'!S:S,'Availability Report - NGL'!$H:$H,'Billability Summary '!$B37,'Availability Report - NGL'!$D:$D,"Active"),0) | O37: =IFERROR(1-AVERAGEIFS('Availability Report - NGL'!T:T,'Availability Report - NGL'!$H:$H,'Billability Summary '!$B37,'Availability Report - NGL'!$D:$D,"Active"),0) | Q37: =AVERAGE(N37:O37) | R37: =1-Q37 | T37: =+SUMIFS('Availability Report - NGL'!#REF!,'Availability Report - NGL'!$H:$H,'Billability Summary '!$B37,'Availability Report - NGL'!$D:$D,"Active") | V37: =+SUMIFS('Availability Report - NGL'!#REF!,'Availability Report - NGL'!$H:$H,'Billability Summary '!$B37,'Availability Report - NGL'!$D:$D,"Active")
B38: Asset & Intelligence | C38: =COUNTIFS('Availability Report - NGL'!$H:$H,'Billability Summary '!$B38,'Availability Report - NGL'!$D:$D,"Active") | D38: =IFERROR(1-AVERAGEIFS('Availability Report - NGL'!I:I,'Availability Report - NGL'!$H:$H,'Billability Summary '!$B38,'Availability Report - NGL'!$D:$D,"Active"),0) | E38: =IFERROR(1-AVERAGEIFS('Availability Report - NGL'!J:J,'Availability Report - NGL'!$H:$H,'Billability Summary '!$B38,'Availability Report - NGL'!$D:$D,"Active"),0) | F38: =IFERROR(1-AVERAGEIFS('Availability Report - NGL'!K:K,'Availability Report - NGL'!$H:$H,'Billability Summary '!$B38,'Availability Report - NGL'!$D:$D,"Active"),0) | G38: =IFERROR(1-AVERAGEIFS('Availability Report - NGL'!L:L,'Availability Report - NGL'!$H:$H,'Billability Summary '!$B38,'Availability Report - NGL'!$D:$D,"Active"),0) | H38: =IFERROR(1-AVERAGEIFS('Availability Report - NGL'!M:M,'Availability Report - NGL'!$H:$H,'Billability Summary '!$B38,'Availability Report - NGL'!$D:$D,"Active"),0) | I38: =IFERROR(1-AVERAGEIFS('Availability Report - NGL'!N:N,'Availability Report - NGL'!$H:$H,'Billability Summary '!$B38,'Availability Report - NGL'!$D:$D,"Active"),0) | J38: =IFERROR(1-AVERAGEIFS('Availability Report - NGL'!O:O,'Availability Report - NGL'!$H:$H,'Billability Summary '!$B38,'Availability Report - NGL'!$D:$D,"Active"),0) | K38: =IFERROR(1-AVERAGEIFS('Availability Report - NGL'!P:P,'Availability Report - NGL'!$H:$H,'Billability Summary '!$B38,'Availability Report - NGL'!$D:$D,"Active"),0) | L38: =IFERROR(1-AVERAGEIFS('Availability Report - NGL'!Q:Q,'Availability Report - NGL'!$H:$H,'Billability Summary '!$B38,'Availability Report - NGL'!$D:$D,"Active"),0) | M38: =IFERROR(1-AVERAGEIFS('Availability Report - NGL'!R:R,'Availability Report - NGL'!$H:$H,'Billability Summary '!$B38,'Availability Report - NGL'!$D:$D,"Active"),0) | N38: =IFERROR(1-AVERAGEIFS('Availability Report - NGL'!S:S,'Availability Report - NGL'!$H:$H,'Billability Summary '!$B38,'Availability Report - NGL'!$D:$D,"Active"),0) | O38: =IFERROR(1-AVERAGEIFS('Availability Report - NGL'!T:T,'Availability Report - NGL'!$H:$H,'Billability Summary '!$B38,'Availability Report - NGL'!$D:$D,"Active"),0) | Q38: =AVERAGE(N38:O38) | R38: =1-Q38 | T38: =+SUMIFS('Availability Report - NGL'!#REF!,'Availability Report - NGL'!$H:$H,'Billability Summary '!$B38,'Availability Report - NGL'!$D:$D,"Active") | V38: =+SUMIFS('Availability Report - NGL'!#REF!,'Availability Report - NGL'!$H:$H,'Billability Summary '!$B38,'Availability Report - NGL'!$D:$D,"Active")
